============================= FAILURES SHORT STACK =============================
_ [doctest] transformers.models.van.modeling_van.VanForImageClassification.forward _
564 
565     ```python
566     >>> from transformers import AutoFeatureExtractor, VanForImageClassification
567     >>> import torch
568     >>> from datasets import load_dataset
569 
570     >>> dataset = load_dataset("huggingface/cats-image")
571     >>> image = dataset["test"]["image"][0]
572 
573     >>> feature_extractor = AutoFeatureExtractor.from_pretrained("van-base")
UNEXPECTED EXCEPTION: OSError("van-base is not a local folder and is not a valid model identifier listed on 'https://huggingface.co/models'\nIf this is a private repository, make sure to pass a token having permission to this repo with `use_auth_token` or log in with `huggingface-cli login` and pass `use_auth_token=True`.")
Traceback (most recent call last):
  File "/__w/transformers/transformers/src/transformers/feature_extraction_utils.py", line 405, in get_feature_extractor_dict
    resolved_feature_extractor_file = cached_path(
  File "/__w/transformers/transformers/src/transformers/file_utils.py", line 1978, in cached_path
    output_path = get_from_cache(
  File "/__w/transformers/transformers/src/transformers/file_utils.py", line 2182, in get_from_cache
    _raise_for_status(r)
  File "/__w/transformers/transformers/src/transformers/file_utils.py", line 2103, in _raise_for_status
    raise RepositoryNotFoundError(f"404 Client Error: Repository Not Found for url: {request.url}")
transformers.file_utils.RepositoryNotFoundError: 404 Client Error: Repository Not Found for url: https://huggingface.co/van-base/resolve/main/preprocessor_config.json
During handling of the above exception, another exception occurred:
Traceback (most recent call last):
  File "/usr/lib/python3.8/doctest.py", line 1336, in __run
    exec(compile(example.source, filename, "single",
  File "<doctest transformers.models.van.modeling_van.VanForImageClassification.forward[5]>", line 1, in <module>
  File "/__w/transformers/transformers/src/transformers/models/auto/feature_extraction_auto.py", line 266, in from_pretrained
    config_dict, _ = FeatureExtractionMixin.get_feature_extractor_dict(pretrained_model_name_or_path, **kwargs)
  File "/__w/transformers/transformers/src/transformers/feature_extraction_utils.py", line 417, in get_feature_extractor_dict
    raise EnvironmentError(
OSError: van-base is not a local folder and is not a valid model identifier listed on 'https://huggingface.co/models'
If this is a private repository, make sure to pass a token having permission to this repo with `use_auth_token` or log in with `huggingface-cli login` and pass `use_auth_token=True`.
/__w/transformers/transformers/src/transformers/models/van/modeling_van.py:573: UnexpectedException
565     ```python
566     >>> from transformers import AutoFeatureExtractor, VanForImageClassification
567     >>> import torch
568     >>> from datasets import load_dataset
569 
570     >>> dataset = load_dataset("huggingface/cats-image")
571     >>> image = dataset["test"]["image"][0]
572 
573     >>> feature_extractor = AutoFeatureExtractor.from_pretrained("van-base")
574     >>> model = VanForImageClassification.from_pretrained("van-base")
UNEXPECTED EXCEPTION: OSError("van-base is not a local folder and is not a valid model identifier listed on 'https://huggingface.co/models'\nIf this is a private repository, make sure to pass a token having permission to this repo with `use_auth_token` or log in with `huggingface-cli login` and pass `use_auth_token=True`.")
Traceback (most recent call last):
  File "/__w/transformers/transformers/src/transformers/configuration_utils.py", line 596, in _get_config_dict
    resolved_config_file = cached_path(
  File "/__w/transformers/transformers/src/transformers/file_utils.py", line 1978, in cached_path
    output_path = get_from_cache(
  File "/__w/transformers/transformers/src/transformers/file_utils.py", line 2182, in get_from_cache
    _raise_for_status(r)
  File "/__w/transformers/transformers/src/transformers/file_utils.py", line 2103, in _raise_for_status
    raise RepositoryNotFoundError(f"404 Client Error: Repository Not Found for url: {request.url}")
transformers.file_utils.RepositoryNotFoundError: 404 Client Error: Repository Not Found for url: https://huggingface.co/van-base/resolve/main/config.json
During handling of the above exception, another exception occurred:
Traceback (most recent call last):
  File "/usr/lib/python3.8/doctest.py", line 1336, in __run
    exec(compile(example.source, filename, "single",
  File "<doctest transformers.models.van.modeling_van.VanForImageClassification.forward[6]>", line 1, in <module>
  File "/__w/transformers/transformers/src/transformers/modeling_utils.py", line 1280, in from_pretrained
    config, model_kwargs = cls.config_class.from_pretrained(
  File "/__w/transformers/transformers/src/transformers/configuration_utils.py", line 521, in from_pretrained
    config_dict, kwargs = cls.get_config_dict(pretrained_model_name_or_path, **kwargs)
  File "/__w/transformers/transformers/src/transformers/configuration_utils.py", line 548, in get_config_dict
    config_dict, kwargs = cls._get_config_dict(pretrained_model_name_or_path, **kwargs)
  File "/__w/transformers/transformers/src/transformers/configuration_utils.py", line 608, in _get_config_dict
    raise EnvironmentError(
OSError: van-base is not a local folder and is not a valid model identifier listed on 'https://huggingface.co/models'
If this is a private repository, make sure to pass a token having permission to this repo with `use_auth_token` or log in with `huggingface-cli login` and pass `use_auth_token=True`.
/__w/transformers/transformers/src/transformers/models/van/modeling_van.py:574: UnexpectedException
567     >>> import torch
568     >>> from datasets import load_dataset
569 
570     >>> dataset = load_dataset("huggingface/cats-image")
571     >>> image = dataset["test"]["image"][0]
572 
573     >>> feature_extractor = AutoFeatureExtractor.from_pretrained("van-base")
574     >>> model = VanForImageClassification.from_pretrained("van-base")
575 
576     >>> inputs = feature_extractor(image, return_tensors="pt")
UNEXPECTED EXCEPTION: NameError("name 'feature_extractor' is not defined")
Traceback (most recent call last):
  File "/usr/lib/python3.8/doctest.py", line 1336, in __run
    exec(compile(example.source, filename, "single",
  File "<doctest transformers.models.van.modeling_van.VanForImageClassification.forward[7]>", line 1, in <module>
NameError: name 'feature_extractor' is not defined
/__w/transformers/transformers/src/transformers/models/van/modeling_van.py:576: UnexpectedException
569 
570     >>> dataset = load_dataset("huggingface/cats-image")
571     >>> image = dataset["test"]["image"][0]
572 
573     >>> feature_extractor = AutoFeatureExtractor.from_pretrained("van-base")
574     >>> model = VanForImageClassification.from_pretrained("van-base")
575 
576     >>> inputs = feature_extractor(image, return_tensors="pt")
577 
578     >>> with torch.no_grad():
UNEXPECTED EXCEPTION: NameError("name 'model' is not defined")
Traceback (most recent call last):
  File "/usr/lib/python3.8/doctest.py", line 1336, in __run
    exec(compile(example.source, filename, "single",
  File "<doctest transformers.models.van.modeling_van.VanForImageClassification.forward[8]>", line 2, in <module>
NameError: name 'model' is not defined
/__w/transformers/transformers/src/transformers/models/van/modeling_van.py:578: UnexpectedException
573     >>> feature_extractor = AutoFeatureExtractor.from_pretrained("van-base")
574     >>> model = VanForImageClassification.from_pretrained("van-base")
575 
576     >>> inputs = feature_extractor(image, return_tensors="pt")
577 
578     >>> with torch.no_grad():
579     ...     logits = model(**inputs).logits
580 
581     >>> # model predicts one of the 1000 ImageNet classes
582     >>> predicted_label = logits.argmax(-1).item()
UNEXPECTED EXCEPTION: NameError("name 'logits' is not defined")
Traceback (most recent call last):
  File "/usr/lib/python3.8/doctest.py", line 1336, in __run
    exec(compile(example.source, filename, "single",
  File "<doctest transformers.models.van.modeling_van.VanForImageClassification.forward[9]>", line 1, in <module>
NameError: name 'logits' is not defined
/__w/transformers/transformers/src/transformers/models/van/modeling_van.py:582: UnexpectedException
574     >>> model = VanForImageClassification.from_pretrained("van-base")
575 
576     >>> inputs = feature_extractor(image, return_tensors="pt")
577 
578     >>> with torch.no_grad():
579     ...     logits = model(**inputs).logits
580 
581     >>> # model predicts one of the 1000 ImageNet classes
582     >>> predicted_label = logits.argmax(-1).item()
583     >>> print(model.config.id2label[predicted_label])
UNEXPECTED EXCEPTION: NameError("name 'model' is not defined")
Traceback (most recent call last):
  File "/usr/lib/python3.8/doctest.py", line 1336, in __run
    exec(compile(example.source, filename, "single",
  File "<doctest transformers.models.van.modeling_van.VanForImageClassification.forward[10]>", line 1, in <module>
NameError: name 'model' is not defined
/__w/transformers/transformers/src/transformers/models/van/modeling_van.py:583: UnexpectedException
_ [doctest] transformers.models.resnet.modeling_resnet.ResNetForImageClassification.forward _
429 
430     ```python
431     >>> from transformers import AutoFeatureExtractor, ResNetForImageClassification
432     >>> import torch
433     >>> from datasets import load_dataset
434 
435     >>> dataset = load_dataset("huggingface/cats-image")
436     >>> image = dataset["test"]["image"][0]
437 
438     >>> feature_extractor = AutoFeatureExtractor.from_pretrained("")
UNEXPECTED EXCEPTION: OSError("We couldn't connect to 'https://huggingface.co/' to load this model and it looks like  is not the path to a directory conaining a preprocessor_config.json file.\nCheckout your internet connection or see how to run the library in offline mode at 'https://huggingface.co/docs/transformers/installation#offline-mode'.")
Traceback (most recent call last):
  File "/__w/transformers/transformers/src/transformers/feature_extraction_utils.py", line 405, in get_feature_extractor_dict
    resolved_feature_extractor_file = cached_path(
  File "/__w/transformers/transformers/src/transformers/file_utils.py", line 1978, in cached_path
    output_path = get_from_cache(
  File "/__w/transformers/transformers/src/transformers/file_utils.py", line 2182, in get_from_cache
    _raise_for_status(r)
  File "/__w/transformers/transformers/src/transformers/file_utils.py", line 2109, in _raise_for_status
    request.raise_for_status()
  File "/usr/local/lib/python3.8/dist-packages/requests/models.py", line 960, in raise_for_status
    raise HTTPError(http_error_msg, response=self)
requests.exceptions.HTTPError: 404 Client Error: Not Found for url: https://huggingface.co//resolve/main/preprocessor_config.json
During handling of the above exception, another exception occurred:
Traceback (most recent call last):
  File "/usr/lib/python3.8/doctest.py", line 1336, in __run
    exec(compile(example.source, filename, "single",
  File "<doctest transformers.models.resnet.modeling_resnet.ResNetForImageClassification.forward[5]>", line 1, in <module>
  File "/__w/transformers/transformers/src/transformers/models/auto/feature_extraction_auto.py", line 266, in from_pretrained
    config_dict, _ = FeatureExtractionMixin.get_feature_extractor_dict(pretrained_model_name_or_path, **kwargs)
  File "/__w/transformers/transformers/src/transformers/feature_extraction_utils.py", line 434, in get_feature_extractor_dict
    raise EnvironmentError(
OSError: We couldn't connect to 'https://huggingface.co/' to load this model and it looks like  is not the path to a directory conaining a preprocessor_config.json file.
Checkout your internet connection or see how to run the library in offline mode at 'https://huggingface.co/docs/transformers/installation#offline-mode'.
/__w/transformers/transformers/src/transformers/models/resnet/modeling_resnet.py:438: UnexpectedException
430     ```python
431     >>> from transformers import AutoFeatureExtractor, ResNetForImageClassification
432     >>> import torch
433     >>> from datasets import load_dataset
434 
435     >>> dataset = load_dataset("huggingface/cats-image")
436     >>> image = dataset["test"]["image"][0]
437 
438     >>> feature_extractor = AutoFeatureExtractor.from_pretrained("")
439     >>> model = ResNetForImageClassification.from_pretrained("")
UNEXPECTED EXCEPTION: OSError("We couldn't connect to 'https://huggingface.co/' to load this model and it looks like  is not the path to a directory containing a config.json file.\nCheckout your internet connection or see how to run the library in offline mode at 'https://huggingface.co/docs/transformers/installation#offline-mode'.")
Traceback (most recent call last):
  File "/__w/transformers/transformers/src/transformers/configuration_utils.py", line 596, in _get_config_dict
    resolved_config_file = cached_path(
  File "/__w/transformers/transformers/src/transformers/file_utils.py", line 1978, in cached_path
    output_path = get_from_cache(
  File "/__w/transformers/transformers/src/transformers/file_utils.py", line 2182, in get_from_cache
    _raise_for_status(r)
  File "/__w/transformers/transformers/src/transformers/file_utils.py", line 2109, in _raise_for_status
    request.raise_for_status()
  File "/usr/local/lib/python3.8/dist-packages/requests/models.py", line 960, in raise_for_status
    raise HTTPError(http_error_msg, response=self)
requests.exceptions.HTTPError: 404 Client Error: Not Found for url: https://huggingface.co//resolve/main/config.json
During handling of the above exception, another exception occurred:
Traceback (most recent call last):
  File "/usr/lib/python3.8/doctest.py", line 1336, in __run
    exec(compile(example.source, filename, "single",
  File "<doctest transformers.models.resnet.modeling_resnet.ResNetForImageClassification.forward[6]>", line 1, in <module>
  File "/__w/transformers/transformers/src/transformers/modeling_utils.py", line 1280, in from_pretrained
    config, model_kwargs = cls.config_class.from_pretrained(
  File "/__w/transformers/transformers/src/transformers/configuration_utils.py", line 521, in from_pretrained
    config_dict, kwargs = cls.get_config_dict(pretrained_model_name_or_path, **kwargs)
  File "/__w/transformers/transformers/src/transformers/configuration_utils.py", line 548, in get_config_dict
    config_dict, kwargs = cls._get_config_dict(pretrained_model_name_or_path, **kwargs)
  File "/__w/transformers/transformers/src/transformers/configuration_utils.py", line 625, in _get_config_dict
    raise EnvironmentError(
OSError: We couldn't connect to 'https://huggingface.co/' to load this model and it looks like  is not the path to a directory containing a config.json file.
Checkout your internet connection or see how to run the library in offline mode at 'https://huggingface.co/docs/transformers/installation#offline-mode'.
/__w/transformers/transformers/src/transformers/models/resnet/modeling_resnet.py:439: UnexpectedException
432     >>> import torch
433     >>> from datasets import load_dataset
434 
435     >>> dataset = load_dataset("huggingface/cats-image")
436     >>> image = dataset["test"]["image"][0]
437 
438     >>> feature_extractor = AutoFeatureExtractor.from_pretrained("")
439     >>> model = ResNetForImageClassification.from_pretrained("")
440 
441     >>> inputs = feature_extractor(image, return_tensors="pt")
UNEXPECTED EXCEPTION: NameError("name 'feature_extractor' is not defined")
Traceback (most recent call last):
  File "/usr/lib/python3.8/doctest.py", line 1336, in __run
    exec(compile(example.source, filename, "single",
  File "<doctest transformers.models.resnet.modeling_resnet.ResNetForImageClassification.forward[7]>", line 1, in <module>
NameError: name 'feature_extractor' is not defined
/__w/transformers/transformers/src/transformers/models/resnet/modeling_resnet.py:441: UnexpectedException
434 
435     >>> dataset = load_dataset("huggingface/cats-image")
436     >>> image = dataset["test"]["image"][0]
437 
438     >>> feature_extractor = AutoFeatureExtractor.from_pretrained("")
439     >>> model = ResNetForImageClassification.from_pretrained("")
440 
441     >>> inputs = feature_extractor(image, return_tensors="pt")
442 
443     >>> with torch.no_grad():
UNEXPECTED EXCEPTION: NameError("name 'model' is not defined")
Traceback (most recent call last):
  File "/usr/lib/python3.8/doctest.py", line 1336, in __run
    exec(compile(example.source, filename, "single",
  File "<doctest transformers.models.resnet.modeling_resnet.ResNetForImageClassification.forward[8]>", line 2, in <module>
NameError: name 'model' is not defined
/__w/transformers/transformers/src/transformers/models/resnet/modeling_resnet.py:443: UnexpectedException
438     >>> feature_extractor = AutoFeatureExtractor.from_pretrained("")
439     >>> model = ResNetForImageClassification.from_pretrained("")
440 
441     >>> inputs = feature_extractor(image, return_tensors="pt")
442 
443     >>> with torch.no_grad():
444     ...     logits = model(**inputs).logits
445 
446     >>> # model predicts one of the 1000 ImageNet classes
447     >>> predicted_label = logits.argmax(-1).item()
UNEXPECTED EXCEPTION: NameError("name 'logits' is not defined")
Traceback (most recent call last):
  File "/usr/lib/python3.8/doctest.py", line 1336, in __run
    exec(compile(example.source, filename, "single",
  File "<doctest transformers.models.resnet.modeling_resnet.ResNetForImageClassification.forward[9]>", line 1, in <module>
NameError: name 'logits' is not defined
/__w/transformers/transformers/src/transformers/models/resnet/modeling_resnet.py:447: UnexpectedException
439     >>> model = ResNetForImageClassification.from_pretrained("")
440 
441     >>> inputs = feature_extractor(image, return_tensors="pt")
442 
443     >>> with torch.no_grad():
444     ...     logits = model(**inputs).logits
445 
446     >>> # model predicts one of the 1000 ImageNet classes
447     >>> predicted_label = logits.argmax(-1).item()
448     >>> print(model.config.id2label[predicted_label])
UNEXPECTED EXCEPTION: NameError("name 'model' is not defined")
Traceback (most recent call last):
  File "/usr/lib/python3.8/doctest.py", line 1336, in __run
    exec(compile(example.source, filename, "single",
  File "<doctest transformers.models.resnet.modeling_resnet.ResNetForImageClassification.forward[10]>", line 1, in <module>
NameError: name 'model' is not defined
/__w/transformers/transformers/src/transformers/models/resnet/modeling_resnet.py:448: UnexpectedException
___ [doctest] transformers.models.resnet.modeling_resnet.ResNetModel.forward ___
387 
388     ```python
389     >>> from transformers import AutoFeatureExtractor, ResNetModel
390     >>> import torch
391     >>> from datasets import load_dataset
392 
393     >>> dataset = load_dataset("huggingface/cats-image")
394     >>> image = dataset["test"]["image"][0]
395 
396     >>> feature_extractor = AutoFeatureExtractor.from_pretrained("")
UNEXPECTED EXCEPTION: OSError("We couldn't connect to 'https://huggingface.co/' to load this model and it looks like  is not the path to a directory conaining a preprocessor_config.json file.\nCheckout your internet connection or see how to run the library in offline mode at 'https://huggingface.co/docs/transformers/installation#offline-mode'.")
Traceback (most recent call last):
  File "/__w/transformers/transformers/src/transformers/feature_extraction_utils.py", line 405, in get_feature_extractor_dict
    resolved_feature_extractor_file = cached_path(
  File "/__w/transformers/transformers/src/transformers/file_utils.py", line 1978, in cached_path
    output_path = get_from_cache(
  File "/__w/transformers/transformers/src/transformers/file_utils.py", line 2182, in get_from_cache
    _raise_for_status(r)
  File "/__w/transformers/transformers/src/transformers/file_utils.py", line 2109, in _raise_for_status
    request.raise_for_status()
  File "/usr/local/lib/python3.8/dist-packages/requests/models.py", line 960, in raise_for_status
    raise HTTPError(http_error_msg, response=self)
requests.exceptions.HTTPError: 404 Client Error: Not Found for url: https://huggingface.co//resolve/main/preprocessor_config.json
During handling of the above exception, another exception occurred:
Traceback (most recent call last):
  File "/usr/lib/python3.8/doctest.py", line 1336, in __run
    exec(compile(example.source, filename, "single",
  File "<doctest transformers.models.resnet.modeling_resnet.ResNetModel.forward[5]>", line 1, in <module>
  File "/__w/transformers/transformers/src/transformers/models/auto/feature_extraction_auto.py", line 266, in from_pretrained
    config_dict, _ = FeatureExtractionMixin.get_feature_extractor_dict(pretrained_model_name_or_path, **kwargs)
  File "/__w/transformers/transformers/src/transformers/feature_extraction_utils.py", line 434, in get_feature_extractor_dict
    raise EnvironmentError(
OSError: We couldn't connect to 'https://huggingface.co/' to load this model and it looks like  is not the path to a directory conaining a preprocessor_config.json file.
Checkout your internet connection or see how to run the library in offline mode at 'https://huggingface.co/docs/transformers/installation#offline-mode'.
/__w/transformers/transformers/src/transformers/models/resnet/modeling_resnet.py:396: UnexpectedException
388     ```python
389     >>> from transformers import AutoFeatureExtractor, ResNetModel
390     >>> import torch
391     >>> from datasets import load_dataset
392 
393     >>> dataset = load_dataset("huggingface/cats-image")
394     >>> image = dataset["test"]["image"][0]
395 
396     >>> feature_extractor = AutoFeatureExtractor.from_pretrained("")
397     >>> model = ResNetModel.from_pretrained("")
UNEXPECTED EXCEPTION: OSError("We couldn't connect to 'https://huggingface.co/' to load this model and it looks like  is not the path to a directory containing a config.json file.\nCheckout your internet connection or see how to run the library in offline mode at 'https://huggingface.co/docs/transformers/installation#offline-mode'.")
Traceback (most recent call last):
  File "/__w/transformers/transformers/src/transformers/configuration_utils.py", line 596, in _get_config_dict
    resolved_config_file = cached_path(
  File "/__w/transformers/transformers/src/transformers/file_utils.py", line 1978, in cached_path
    output_path = get_from_cache(
  File "/__w/transformers/transformers/src/transformers/file_utils.py", line 2182, in get_from_cache
    _raise_for_status(r)
  File "/__w/transformers/transformers/src/transformers/file_utils.py", line 2109, in _raise_for_status
    request.raise_for_status()
  File "/usr/local/lib/python3.8/dist-packages/requests/models.py", line 960, in raise_for_status
    raise HTTPError(http_error_msg, response=self)
requests.exceptions.HTTPError: 404 Client Error: Not Found for url: https://huggingface.co//resolve/main/config.json
During handling of the above exception, another exception occurred:
Traceback (most recent call last):
  File "/usr/lib/python3.8/doctest.py", line 1336, in __run
    exec(compile(example.source, filename, "single",
  File "<doctest transformers.models.resnet.modeling_resnet.ResNetModel.forward[6]>", line 1, in <module>
  File "/__w/transformers/transformers/src/transformers/modeling_utils.py", line 1280, in from_pretrained
    config, model_kwargs = cls.config_class.from_pretrained(
  File "/__w/transformers/transformers/src/transformers/configuration_utils.py", line 521, in from_pretrained
    config_dict, kwargs = cls.get_config_dict(pretrained_model_name_or_path, **kwargs)
  File "/__w/transformers/transformers/src/transformers/configuration_utils.py", line 548, in get_config_dict
    config_dict, kwargs = cls._get_config_dict(pretrained_model_name_or_path, **kwargs)
  File "/__w/transformers/transformers/src/transformers/configuration_utils.py", line 625, in _get_config_dict
    raise EnvironmentError(
OSError: We couldn't connect to 'https://huggingface.co/' to load this model and it looks like  is not the path to a directory containing a config.json file.
Checkout your internet connection or see how to run the library in offline mode at 'https://huggingface.co/docs/transformers/installation#offline-mode'.
/__w/transformers/transformers/src/transformers/models/resnet/modeling_resnet.py:397: UnexpectedException
390     >>> import torch
391     >>> from datasets import load_dataset
392 
393     >>> dataset = load_dataset("huggingface/cats-image")
394     >>> image = dataset["test"]["image"][0]
395 
396     >>> feature_extractor = AutoFeatureExtractor.from_pretrained("")
397     >>> model = ResNetModel.from_pretrained("")
398 
399     >>> inputs = feature_extractor(image, return_tensors="pt")
UNEXPECTED EXCEPTION: NameError("name 'feature_extractor' is not defined")
Traceback (most recent call last):
  File "/usr/lib/python3.8/doctest.py", line 1336, in __run
    exec(compile(example.source, filename, "single",
  File "<doctest transformers.models.resnet.modeling_resnet.ResNetModel.forward[7]>", line 1, in <module>
NameError: name 'feature_extractor' is not defined
/__w/transformers/transformers/src/transformers/models/resnet/modeling_resnet.py:399: UnexpectedException
392 
393     >>> dataset = load_dataset("huggingface/cats-image")
394     >>> image = dataset["test"]["image"][0]
395 
396     >>> feature_extractor = AutoFeatureExtractor.from_pretrained("")
397     >>> model = ResNetModel.from_pretrained("")
398 
399     >>> inputs = feature_extractor(image, return_tensors="pt")
400 
401     >>> with torch.no_grad():
UNEXPECTED EXCEPTION: NameError("name 'model' is not defined")
Traceback (most recent call last):
  File "/usr/lib/python3.8/doctest.py", line 1336, in __run
    exec(compile(example.source, filename, "single",
  File "<doctest transformers.models.resnet.modeling_resnet.ResNetModel.forward[8]>", line 2, in <module>
NameError: name 'model' is not defined
/__w/transformers/transformers/src/transformers/models/resnet/modeling_resnet.py:401: UnexpectedException
395 
396     >>> feature_extractor = AutoFeatureExtractor.from_pretrained("")
397     >>> model = ResNetModel.from_pretrained("")
398 
399     >>> inputs = feature_extractor(image, return_tensors="pt")
400 
401     >>> with torch.no_grad():
402     ...     outputs = model(**inputs)
403 
404     >>> last_hidden_states = outputs.last_hidden_state
UNEXPECTED EXCEPTION: NameError("name 'outputs' is not defined")
Traceback (most recent call last):
  File "/usr/lib/python3.8/doctest.py", line 1336, in __run
    exec(compile(example.source, filename, "single",
  File "<doctest transformers.models.resnet.modeling_resnet.ResNetModel.forward[9]>", line 1, in <module>
NameError: name 'outputs' is not defined
/__w/transformers/transformers/src/transformers/models/resnet/modeling_resnet.py:404: UnexpectedException
396     >>> feature_extractor = AutoFeatureExtractor.from_pretrained("")
397     >>> model = ResNetModel.from_pretrained("")
398 
399     >>> inputs = feature_extractor(image, return_tensors="pt")
400 
401     >>> with torch.no_grad():
402     ...     outputs = model(**inputs)
403 
404     >>> last_hidden_states = outputs.last_hidden_state
405     >>> list(last_hidden_states.shape)
UNEXPECTED EXCEPTION: NameError("name 'last_hidden_states' is not defined")
Traceback (most recent call last):
  File "/usr/lib/python3.8/doctest.py", line 1336, in __run
    exec(compile(example.source, filename, "single",
  File "<doctest transformers.models.resnet.modeling_resnet.ResNetModel.forward[10]>", line 1, in <module>
NameError: name 'last_hidden_states' is not defined
/__w/transformers/transformers/src/transformers/models/resnet/modeling_resnet.py:405: UnexpectedException
